<mujoco model="inverted_pendulum">
    <compiler angle="radian" coordinate="local"/>
    <option timestep="0.01" gravity="0 0 -9.81"/>
    <default>
        <joint limited="false" damping="0"/>
        <geom type="box" rgba="0.8 0.6 0.4 1"/>
    </default>
    <worldbody>
        <geom name="ground" type="plane" pos="0 0 0" size="10 10 0.1" rgba="0.2 0.2 0.2 1"/>
        <body name="cart" pos="0 0 0.1">
            <inertial mass="1.0" pos="0 0 0" diaginertia="0.1 0.4 0.4"/>
            <joint name="slider" type="slide" axis="1 0 0"/>
            <geom size="0.2 0.1 0.1"/>
            <body name="pole" pos="0 0 0.1">
                <inertial mass="0.2" pos="0 0 0.4" diaginertia="0.01 0.01 0.0001"/>
                <joint name="hinge" type="hinge" axis="0 1 0"/>
                <geom size="0.02 0.02 0.4" pos="0 0 0.4"/>
            </body>
        </body>
    </worldbody>
    <actuator>
        <motor joint="slider" ctrlrange="-1000 1000"/>
    </actuator>
</mujoco>